Workbook

Sheet Upcoming IPOs
A1: S.No | B1: IPO / Company Name | C1: DRHP Filing Date (SEBI) | D1: Latest Draft Filing Date | E1: Latest Draft Document | F1: Filing Route | G1: IPO Issue (Open) Date | H1: IPO Status | I1: IPO Size (₹ Cr) per DRHP | J1: Fresh Issue (₹ Cr) | K1: OFS (₹ Cr) | L1: Total Offer (No. of Shares) | M1: Fresh Issue (No. of Shares) | N1: OFS (No. of Shares) | O1: Offer Terms per DRHP | P1: Size Basis | Q1: DRHP PDF (SEBI) | R1: SEBI Filing Page | S1: Draft Abridged Prospectus | T1: Addenda / Corrigenda Filed | U1: IPO Issue Open Date (web search) | V1: IPO Issue Close Date (web search) | W1: Listing Date (web search) | X1: Web Search Status | Y1: Web Search Note | Z1: Web Search Source
A2: 1 | B2: S. D. INTERNATIONAL LIMITED | C2: 46295 | D2: 46295 | E2: DRHP | F2: Regular DRHP | H2: DRHP filed — issue dates not announced | O2: Not read — see DRHP PDF | P2: Offer terms not extracted — open the DRHP PDF | Q2: https://www.sebi.gov.in/sebi_data/attachdocs/sep-2026/1790767812069_1376.pdf | R2: https://www.sebi.gov.in/filings/public-issues/sep-2026/s-d-international-limited_104826.html | T2: 0 | X2: Dates not announced | Y2: DRHP filed; no IPO dates found
A3: 2 | B3: S G Encon Limited | C3: 46295 | D3: 46295 | E3: DRHP | F3: Regular DRHP | H3: DRHP filed — issue dates not announced | L3: 8561700 | M3: 7190400 | N3: 1371300 | O3: Fresh issue up to 7,190,400 sh + OFS up to 1,371,300 sh | P3: DRHP states number of shares only (DRHP cover) — ₹ size depends on price band | Q3: https://www.sebi.gov.in/sebi_data/attachdocs/sep-2026/1790767812069_1377.pdf | R3: https://www.sebi.gov.in/filings/public-issues/sep-2026/s-g-encon-limited_104828.html | T3: 0 | X3: Dates not announced | Y3: DRHP filed; no IPO dates found
A4: 3 | B4: J B ECOTEX LIMITED | C4: 46295 | D4: 46295 | E4: DRHP | F4: Regular DRHP | H4: DRHP filed — issue dates not announced | O4: Not read — see DRHP PDF | P4: Offer terms not extracted — open the DRHP PDF | Q4: https://www.sebi.gov.in/sebi_data/attachdocs/sep-2026/1790767812069_1378.pdf | R4: https://www.sebi.gov.in/filings/public-issues/sep-2026/j-b-ecotex-limited_104830.html | T4: 0 | X4: Dates not announced | Y4: DRHP filed; dates not announced | Z4: https://www.chittorgarh.com/ipo/j-b-ecotex-ipo/3311/
A5: 4 | B5: ULTRAVIBRANT INTEGRATED ENERGY LIMITED | C5: 46294 | D5: 46294 | E5: DRHP | F5: Regular DRHP | H5: DRHP filed — issue dates not announced | L5: 14500000 | M5: 12000000 | N5: 2500000 | O5: Fresh issue up to 12,000,000 sh + OFS up to 2,500,000 sh | P5: DRHP states number of shares only (DRHP cover) — ₹ size depends on price band | Q5: https://www.sebi.gov.in/sebi_data/attachdocs/sep-2026/1790681405842_1375.pdf | R5: https://www.sebi.gov.in/filings/public-issues/sep-2026/ultravibrant-integrated-energy-limited_104809.html | T5: 0 | X5: Dates not announced | Y5: DRHP filed; no IPO dates found
A6: 5 | B6: Iris Global Services Limited | C6: 46293 | D6: 46293 | E6: DRHP | F6: Regular DRHP | H6: DRHP filed — issue dates not announced | O6: Not read — see DRHP PDF | P6: Offer terms not extracted — open the DRHP PDF | Q6: https://www.sebi.gov.in/sebi_data/attachdocs/sep-2026/1790743844411.pdf | R6: https://www.sebi.gov.in/filings/public-issues/sep-2026/iris-global-services-limited-drhp_104746.html | S6: https://www.sebi.gov.in/sebi_data/commondocs/sep-2026/Iris%20Global%20Services%20Limited%20-%20DAP_p.pdf | T6: 0 | X6: Dates not announced | Y6: DRHP filed; no IPO dates found
A7: 6 | B7: JSW One Platforms Limited | C7: 46290 | D7: 46290 | E7: DRHP | F7: Regular DRHP | H7: DRHP filed — issue dates not announced | I7: 3054.01 | J7: 1300 | K7: 1754.01 | O7: Fresh issue up to ₹1,300.00 Cr + OFS up to ₹1,754.01 Cr | P7: ₹ amount stated in DRHP cover | Q7: https://www.sebi.gov.in/sebi_data/attachdocs/sep-2026/1790585630648.pdf | R7: https://www.sebi.gov.in/filings/public-issues/sep-2026/jsw-one-platforms-limited-drhp_104742.html | S7: https://www.sebi.gov.in/sebi_data/commondocs/sep-2026/JSW%20One%20Platforms%20Limited%20-%20Draft%20Abridged%20Prospectus_p.pdf | T7: 0 | X7: Dates not announced | Y7: DRHP filed Sep-2026; dates not announced | Z7: https://www.chittorgarh.com/ipo/jsw-one-platform-ipo/3295/
A8: 7 | B8: Anjali Labtech Limited | C8: 46290 | D8: 46290 | E8: UDRHP-I | F8: Confidential pre-filing (UDRHP-I published) | H8: DRHP filed — issue dates not announced | O8: Not read — see DRHP PDF | P8: Offer terms not extracted — open the DRHP PDF | Q8: https://www.sebi.gov.in/sebi_data/attachdocs/sep-2026/1790320604407.pdf | R8: https://www.sebi.gov.in/filings/public-issues/sep-2026/anjali-labtech-limited-udrhp-i_104737.html | S8: https://www.sebi.gov.in/sebi_data/commondocs/sep-2026/Anjali%20Labtech%20Limited%20-%20DAP_p.pdf | T8: 0 | X8: Dates not announced | Y8: SEBI nod Feb-2026; UDRHP-I filed Sep-2026; dates not announced | Z8: https://www.chittorgarh.com/ipo/anjali-labtech-ipo/2786/
A9: 8 | B9: VARDAAN BIOTECH LIMITED | C9: 46287 | D9: 46287 | E9: DRHP | F9: Regular DRHP | H9: DRHP filed — issue dates not announced | O9: Not read — see DRHP PDF | P9: Offer terms not extracted — open the DRHP PDF | Q9: https://www.sebi.gov.in/sebi_data/attachdocs/sep-2026/1790076604769_1355.pdf | R9: https://www.sebi.gov.in/filings/public-issues/sep-2026/vardaan-biotech-limited-drhp_104652.html | S9: https://www.sebi.gov.in/sebi_data/commondocs/sep-2026/VARDAAN%20BIOTECH%20LIMITED_p.pdf | T9: 0 | X9: Dates not announced | Y9: Refiled on mainboard; earlier SME DRHP withdrawn Jul-2024; no dates | Z9: https://www.barandbench.com/law-firms/dealstreet/legacy-law-offices-acts-on-vardaan-biotech-90-crore-ipo
A10: 9 | B10: Hi-Tech Flow Solutions Limited | C10: 46287 | D10: 46287 | E10: DRHP | F10: Regular DRHP | H10: DRHP filed — issue dates not announced | O10: Not read — see DRHP PDF | P10: Offer terms not extracted — open the DRHP PDF | Q10: https://www.sebi.gov.in/sebi_data/attachdocs/sep-2026/1790058959002.pdf | R10: https://www.sebi.gov.in/filings/public-issues/sep-2026/hi-tech-flow-solutions-limited-drhp_104635.html | S10: https://www.sebi.gov.in/sebi_data/commondocs/sep-2026/HitechFlowSolutionsDAP_p.pdf | T10: 0 | X10: Dates not announced | Y10: DRHP filed; no IPO dates found
A11: 10 | B11: Madhur Iron & Steel India Limited | C11: 46059 | D11: 46283 | E11: DRHP | F11: Regular DRHP | H11: DRHP filed — issue dates not announced | L11: 10000000 | M11: 10000000 | O11: Fresh issue up to 10,000,000 sh | P11: DRHP states number of shares only (DRHP cover) — ₹ size depends on price band | Q11: https://www.sebi.gov.in/sebi_data/attachdocs/sep-2026/1789720399852.pdf | R11: https://www.sebi.gov.in/filings/public-issues/sep-2026/madhur-iron-and-steel-india-limited-drhp_104575.html | S11: https://www.sebi.gov.in/sebi_data/commondocs/sep-2026/Madhur%20Iron%20And%20Steel%20India%20Limited%20-%20Draft%20AP_p.pdf | T11: 0 | X11: Dates not announced | Y11: Earlier DRHP withdrawn Mar-2026; fresh DRHP Sep-2026; no IPO dates | Z11: https://www.chittorgarh.com/ipo/madhur-iron-and-steel-ipo/2855/
A12: 11 | B12: ANCHOR OFFSHORE SERVICES LIMITED | C12: 46283 | D12: 46283 | E12: DRHP | F12: Regular DRHP | H12: DRHP filed — issue dates not announced | L12: 7000000 | M12: 6400000 | N12: 600000 | O12: Fresh issue up to 6,400,000 sh + OFS up to 600,000 sh | P12: DRHP states number of shares only (DRHP cover) — ₹ size depends on price band | Q12: https://www.sebi.gov.in/sebi_data/attachdocs/sep-2026/1789731006415_1354.pdf | R12: https://www.sebi.gov.in/filings/public-issues/sep-2026/anchor-offshore-services-limited-drhp_104580.html | S12: https://www.sebi.gov.in/sebi_data/commondocs/sep-2026/Anchor%20Offshore%20Services%20Limited-DA_p.pdf | T12: 0 | X12: Dates not announced | Y12: DRHP filed; no IPO dates found
A13: 12 | B13: IBERIA PHARMACEUTICALS INDIA LIMITED | C13: 46282 | D13: 46282 | E13: DRHP | F13: Regular DRHP | H13: DRHP filed — issue dates not announced | O13: Not read — see DRHP PDF | P13: Offer terms not extracted — open the DRHP PDF | Q13: https://www.sebi.gov.in/sebi_data/attachdocs/sep-2026/1789635115853.pdf | R13: https://www.sebi.gov.in/filings/public-issues/sep-2026/iberia-pharmaceuticals-india-limited-drhp_104542.html | S13: https://www.sebi.gov.in/sebi_data/commondocs/sep-2026/IBERIA%20PHARMACEUTICALS%20INDIA%20LIMITED_p.pdf | T13: 0 | X13: Dates not announced | Y13: DRHP filed; no IPO dates found
A14: 13 | B14: Maharashtra Oil Extractions Limited | C14: 46280 | D14: 46280 | E14: DRHP | F14: Regular DRHP | H14: DRHP filed — issue dates not announced | O14: Not read — see DRHP PDF | P14: Offer terms not extracted — open the DRHP PDF | Q14: https://www.sebi.gov.in/sebi_data/attachdocs/sep-2026/1789531323564.pdf | R14: https://www.sebi.gov.in/filings/public-issues/sep-2026/maharashtra-oil-extractions-limited-drhp_104503.html | S14: https://www.sebi.gov.in/sebi_data/commondocs/sep-2026/Maharashtra%20Oil%20Extractions%20Limited%20-%20DAP_p.pdf | T14: 0 | X14: Dates not announced | Y14: DRHP filed; no IPO dates found
A15: 14 | B15: NOPAPERFORMS SOLUTIONS LIMITED | C15: 46276 | D15: 46276 | E15: UDRHP-I | F15: Confidential pre-filing (UDRHP-I published) | H15: DRHP filed — issue dates not announced | J15: 375 | N15: 38422392 | O15: Fresh issue up to ₹375.00 Cr + OFS up to 38,422,392 sh | P15: Part of offer stated in ₹, rest in shares only (DRHP cover) — total depends on price band | Q15: https://www.sebi.gov.in/sebi_data/attachdocs/sep-2026/1789104761658.pdf | R15: https://www.sebi.gov.in/filings/public-issues/sep-2026/nopaperforms-solutions-limited-udrhp-1_104427.html | S15: https://www.sebi.gov.in/sebi_data/commondocs/sep-2026/NOPAPERFORMS%20SOLUTIONS%20LIMITED%20-%20DAP_p.pdf | T15: 0 | X15: Dates not announced | Y15: SEBI nod Mar-2026; UDRHP-I filed Sep-2026; dates not announced | Z15: https://www.chittorgarh.com/ipo/nopaperforms-solutions-ipo/2796/
A16: 15 | B16: M K C AGRO FRESH LIMITED | C16: 46276 | D16: 46276 | E16: DRHP | F16: Regular DRHP | H16: DRHP filed — issue dates not announced | L16: 16810751 | M16: 9999000 | N16: 6811751 | O16: Fresh issue up to 9,999,000 sh + OFS up to 6,811,751 sh | P16: DRHP states number of shares only (DRHP cover) — ₹ size depends on price band | Q16: https://www.sebi.gov.in/sebi_data/attachdocs/sep-2026/1789111806400_1350.pdf | R16: https://www.sebi.gov.in/filings/public-issues/sep-2026/m-k-c-agro-fresh-limited-drhp_104430.html | S16: https://www.sebi.gov.in/sebi_data/commondocs/sep-2026/M%20K%20C%20AGRO%20FRESH%20LIMITED%20-%20DAP_p.pdf | T16: 0 | X16: Dates not announced | Y16: DRHP filed; no IPO dates found
A17: 16 | B17: Torrent Gas Limited | C17: 46274 | D17: 46274 | E17: UDRHP-I | F17: Confidential pre-filing (UDRHP-I published) | H17: DRHP filed — issue dates not announced | L17: 335000000 | N17: 335000000 | O17: OFS up to 335,000,000 sh | P17: DRHP states number of shares only (DRHP cover) — ₹ size depends on price band | Q17: https://www.sebi.gov.in/sebi_data/attachdocs/sep-2026/1788937260208.PDF | R17: https://www.sebi.gov.in/filings/public-issues/sep-2026/torrent-gas-limited-udrhp-i_104350.html | S17: https://www.sebi.gov.in/sebi_data/commondocs/sep-2026/Torrent%20Gas%20Limited%20-%20DAP_p.pdf | T17: 0 | X17: Dates not announced | Y17: Confidential filing cleared Jun-2026; UDRHP-I Sep-2026; dates not announced | Z17: https://ipowatch.in/torrent-gas-ipo/
A18: 17 | B18: Mahanadi Coalfields Ltd | C18: 46269 | D18: 46269 | E18: DRHP | F18: Regular DRHP | H18: DRHP filed — issue dates not announced | O18: Not read — see DRHP PDF | P18: Offer terms not extracted — open the DRHP PDF | Q18: https://www.sebi.gov.in/sebi_data/attachdocs/sep-2026/1788761365481.pdf | R18: https://www.sebi.gov.in/filings/public-issues/sep-2026/mahanadi-coalfields-ltd-drhp_104290.html | S18: https://www.sebi.gov.in/sebi_data/commondocs/sep-2026/Mahanadi%20Coalfields%20Limited%20_Draft%20Abridged%20Prospectus_p.pdf | T18: 0 | X18: Dates not announced | Y18: DRHP filed; dates not announced | Z18: https://www.chittorgarh.com/ipo/mahanadi-coalfields-ipo/3247/
A19: 18 | B19: India Exposition Mart Limited | C19: 44628 | D19: 46269 | E19: DRHP | F19: Regular DRHP | H19: DRHP filed — issue dates not announced | O19: Not read — see DRHP PDF | P19: Offer terms not extracted — open the DRHP PDF | Q19: https://www.sebi.gov.in/sebi_data/attachdocs/sep-2026/1788507005445_1348.pdf | R19: https://www.sebi.gov.in/filings/public-issues/sep-2026/india-exposition-mart-limited_104273.html | T19: 0 | X19: Dates not announced | Y19: Refiled DRHP 2026; dates not announced | Z19: https://www.chittorgarh.com/ipo/india-exposition-mart-ipo/3225/
A20: 19 | B20: Sembcorp Green Infra Limited | C20: 46266 | D20: 46266 | E20: DRHP | F20: Regular DRHP | H20: DRHP filed — issue dates not announced | I20: 3750 | J20: 3750 | O20: Fresh issue up to ₹3,750.00 Cr | P20: ₹ amount stated in DRHP cover | Q20: https://www.sebi.gov.in/sebi_data/attachdocs/sep-2026/1788245484072.pdf | R20: https://www.sebi.gov.in/filings/public-issues/sep-2026/sembcorp-green-infra-limited-drhp_104162.html | S20: https://www.sebi.gov.in/sebi_data/commondocs/sep-2026/Sembcorp%20Green%20Infra%20Limited%20-%20Draft%20Abridged%20Prospectus_p.pdf | T20: 0 | X20: Dates not announced | Y20: DRHP filed Aug/Sep-2026; dates not announced | Z20: https://www.chittorgarh.com/ipo/sembcorp-green-infra-ipo/3240/
A21: 20 | B21: Kataria Dhulchand Pannalal Jewellers Limited | C21: 46266 | D21: 46266 | E21: DRHP | F21: Regular DRHP | H21: DRHP filed — issue dates not announced | L21: 16000000 | M21: 16000000 | O21: Fresh issue up to 16,000,000 sh | P21: DRHP states number of shares only (DRHP cover) — ₹ size depends on price band | Q21: https://www.sebi.gov.in/sebi_data/attachdocs/sep-2026/1788262207109_1345.pdf | R21: https://www.sebi.gov.in/filings/public-issues/sep-2026/kataria-dhulchand-pannalal-jewellers-limited-drhp_104178.html | S21: https://www.sebi.gov.in/sebi_data/commondocs/sep-2026/Kataria%20Dhulchand%20Pannalal%20Jewellers%20Ltd%20-%20DAP_p.pdf | T21: 0 | X21: Dates not announced | Y21: DRHP filed; no IPO dates found
A22: 21 | B22: ARAGEN LIFE SCIENCES LIMITED | C22: 46266 | D22: 46266 | E22: DRHP | F22: Regular DRHP | H22: DRHP filed — issue dates not announced | O22: Not read — see DRHP PDF | P22: Offer terms not extracted — open the DRHP PDF | Q22: https://www.sebi.gov.in/sebi_data/attachdocs/sep-2026/1788238496589.pdf | R22: https://www.sebi.gov.in/filings/public-issues/sep-2026/aragen-life-sciences-limited-drhp_104157.html | S22: https://www.sebi.gov.in/sebi_data/commondocs/sep-2026/ARAGEN%20LIFE%20SCIENCES%20LIMITED%20-%20DAP_p.pdf | T22: 0 | X22: Dates not announced | Y22: DRHP filed Aug-2026; IPO dates not announced | Z22: https://ipowatch.in/aragen-life-sciences-ipo/
A23: 22 | B23: ATOMBERG TECHNOLOGIES LIMITED | C23: 46261 | D23: 46261 | E23: DRHP | F23: Regular DRHP | H23: DRHP filed — issue dates not announced | J23: 450 | N23: 76541851 | O23: Fresh issue up to ₹450.00 Cr + OFS up to 76,541,851 sh | P23: Part of offer stated in ₹, rest in shares only (DRHP cover) — total depends on price band | Q23: https://www.sebi.gov.in/sebi_data/attachdocs/aug-2026/1787809930622.pdf | R23: https://www.sebi.gov.in/filings/public-issues/aug-2026/atomberg-technologies-limited-drhp_104037.html | S23: https://www.sebi.gov.in/sebi_data/commondocs/aug-2026/ATOMBERG%20TECHNOLOGIES%20LIMITED%20-%20AP_p.pdf | T23: 0 | X23: Dates not announced | Y23: DRHP filed Aug-2026; Rs450cr fresh + OFS; dates not announced | Z23: https://www.chittorgarh.com/ipo/atomberg-technologies-ipo/3227/
A24: 23 | B24: Nobel Hygiene Limited | C24: 46259 | D24: 46259 | E24: DRHP | F24: Regular DRHP | H24: DRHP filed — issue dates not announced | O24: Not read — see DRHP PDF | P24: Offer terms not extracted — open the DRHP PDF | Q24: https://www.sebi.gov.in/sebi_data/attachdocs/aug-2026/1787650339639.pdf | R24: https://www.sebi.gov.in/filings/public-issues/aug-2026/nobel-hygiene-limited-drhp_103938.html | S24: https://www.sebi.gov.in/sebi_data/commondocs/aug-2026/Nobel%20Hygiene%20Limited%20-%20Draft%20Abridged%20Prospectus_p.pdf | T24: 0 | X24: Dates not announced | Y24: DRHP filed Aug-2026; dates not announced | Z24: https://www.kotakneo.com/news/ipos/nobel-hygiene-files-drhp-for-rs-150-crore-ipo-after-profit-jumps-nearly-100-fold-in-fy26/
A25: 24 | B25: M P STEEL (INDIA) LIMITED | C25: 46259 | D25: 46259 | E25: DRHP | F25: Regular DRHP | H25: DRHP filed — issue dates not announced | O25: Not read — see DRHP PDF | P25: Offer terms not extracted — open the DRHP PDF | Q25: https://www.sebi.gov.in/sebi_data/attachdocs/aug-2026/1787653298920.pdf | R25: https://www.sebi.gov.in/filings/public-issues/aug-2026/m-p-steel-india-limited-drhp_103990.html | S25: https://www.sebi.gov.in/sebi_data/commondocs/aug-2026/MPSteel-Draft%20Abridged%20Prospectus_p.pdf | T25: 0 | X25: Dates not announced | Y25: DRHP filed Aug-2026; dates not announced (not MPK Steels SME) | Z25: https://www.chittorgarh.com/ipo/m-p-steel-ipo/3229/
A26: 25 | B26: JAY JAGDAMBA LIMITED | C26: 46259 | D26: 46259 | E26: UDRHP-I | F26: Confidential pre-filing (UDRHP-I published) | H26: DRHP filed — issue dates not announced | J26: 600 | N26: 15000000 | O26: Fresh issue up to ₹600.00 Cr + OFS up to 15,000,000 sh | P26: Part of offer stated in ₹, rest in shares only (DRHP cover) — total depends on price band | Q26: https://www.sebi.gov.in/sebi_data/attachdocs/aug-2026/1787637173016.pdf | R26: https://www.sebi.gov.in/filings/public-issues/aug-2026/jay-jagdamba-limited-udrhp_103937.html | S26: https://www.sebi.gov.in/sebi_data/commondocs/aug-2026/Jay%20Jagdamba%20Limited%20Draft%20Abridged%20Prospectus_p.pdf | T26: 0 | X26: Dates not announced | Y26: SEBI nod Jan-2026; UDRHP-I Aug-2026; dates not announced | Z26: https://www.chittorgarh.com/ipo/jay-jagdamba-ipo/2528/
A27: 26 | B27: AVAADA ELECTRO LIMITED | C27: 46259 | D27: 46259 | E27: UDRHP-I | F27: Confidential pre-filing (UDRHP-I published) | H27: DRHP filed — issue dates not announced | O27: Not read — see DRHP PDF | P27: Offer terms not extracted — open the DRHP PDF | Q27: https://www.sebi.gov.in/sebi_data/attachdocs/aug-2026/1787804677669.pdf | R27: https://www.sebi.gov.in/filings/public-issues/aug-2026/avaada-electro-limited-udrhp_104034.html | S27: https://www.sebi.gov.in/sebi_data/commondocs/aug-2026/Avaada%20Electro%20Limited%20-%20Draft%20Abridged%20Prospectus_p.pdf | T27: 0 | X27: Dates not announced | Y27: SEBI nod Apr-2026; Rs7,600cr; dates not announced | Z27: https://www.chittorgarh.com/ipo/avaada-electro-ipo/2790/
A28: 27 | B28: GEMINI EDIBLES & FATS INDIA LIMITED | C28: 44417 | D28: 46256 | E28: DRHP | F28: Regular DRHP | H28: DRHP filed — issue dates not announced | O28: Not read — see DRHP PDF | P28: Offer terms not extracted — open the DRHP PDF | Q28: https://www.sebi.gov.in/sebi_data/attachdocs/aug-2026/1787803545833.pdf | R28: https://www.sebi.gov.in/filings/public-issues/aug-2026/gemini-edibles-and-fats-india-limited-drhp_104032.html | S28: https://www.sebi.gov.in/sebi_data/commondocs/aug-2026/Gemini%20Edibles%20&%20Fats%20India%20Ltd.%20-%20Draft%20Abridged%20Prospectus_p.pdf | T28: 1 | X28: Dates not announced | Y28: 2021 DRHP was put in abeyance; refiled Aug-2026; dates not announced | Z28: https://www.chittorgarh.com/ipo/gemini-edibles-fats-india-ipo/3238/
A29: 28 | B29: Avtar Steel Limited | C29: 46255 | D29: 46255 | E29: DRHP | F29: Regular DRHP | H29: DRHP filed — issue dates not announced | O29: Not read — see DRHP PDF | P29: Offer terms not extracted — open the DRHP PDF | Q29: https://www.sebi.gov.in/sebi_data/attachdocs/aug-2026/1787311805039_1343.pdf | R29: https://www.sebi.gov.in/filings/public-issues/aug-2026/avtar-steel-limited-drhp_103867.html | S29: https://www.sebi.gov.in/sebi_data/commondocs/aug-2026/Avtar%20Steel%20Limited%20-%20Draft%20Abridged%20Prospectus_p.pdf | T29: 0 | X29: Dates not announced | Y29: DRHP filed Aug-2026; Rs585cr fresh issue; dates not announced | Z29: https://www.businesstoday.in/markets/ipo-corner/story/avtar-steel-files-draft-ipo-papers-with-sebi-to-raise-rs-585-crore-through-fresh-issue-549604-2026-08-17
A30: 29 | B30: TABLESPACE TECHNOLOGIES LIMITED | C30: 46252 | D30: 46252 | E30: DRHP | F30: Regular DRHP | H30: DRHP filed — issue dates not announced | O30: Not read — see DRHP PDF | P30: Offer terms not extracted — open the DRHP PDF | Q30: https://www.sebi.gov.in/sebi_data/attachdocs/aug-2026/1787037217420.pdf | R30: https://www.sebi.gov.in/filings/public-issues/aug-2026/tablespace-technologies-limited-drhp_103710.html | S30: https://www.sebi.gov.in/sebi_data/commondocs/aug-2026/TABLESPACE%20TECHNOLOGIES%20LIMITED%20-%20DAP_p.pdf | T30: 0 | X30: Dates not announced | Y30: DRHP filed Aug-2026; dates not announced | Z30: https://www.chittorgarh.com/ipo/tablespace-technologies-ipo/3218/
A31: 30 | B31: Svatantra Microfin Limited | C31: 46251 | D31: 46251 | E31: DRHP | F31: Regular DRHP | H31: DRHP filed — issue dates not announced | I31: 3000 | J31: 1500 | K31: 1500 | O31: Fresh issue up to ₹1,500.00 Cr + OFS up to ₹1,500.00 Cr | P31: ₹ amount stated in DRHP cover | Q31: https://www.sebi.gov.in/sebi_data/attachdocs/aug-2026/1787135219223.pdf | R31: https://www.sebi.gov.in/filings/public-issues/aug-2026/svatantra-microfin-limited-drhp_103765.html | S31: https://www.sebi.gov.in/sebi_data/commondocs/aug-2026/Svatantra%20Microfin%20Limited%20%20-%20DAP_p.pdf | T31: 0 | X31: Dates not announced | Y31: DRHP filed Aug-2026; Rs3,000cr; dates not announced | Z31: https://www.chittorgarh.com/ipo/svatantra-microfin-ipo/3220/
A32: 31 | B32: Muthoot Fincorp Limited | C32: 46251 | D32: 46251 | E32: DRHP | F32: Regular DRHP | H32: DRHP filed — issue dates not announced | O32: Not read — see DRHP PDF | P32: Offer terms not extracted — open the DRHP PDF | Q32: https://www.sebi.gov.in/sebi_data/attachdocs/aug-2026/1787032236785.pdf | R32: https://www.sebi.gov.in/filings/public-issues/aug-2026/muthoot-fincorp-limited-drhp_103697.html | S32: https://www.sebi.gov.in/sebi_data/commondocs/aug-2026/Muthoot%20Fincorp%20DAP_p.pdf | T32: 0 | X32: Dates not announced | Y32: DRHP filed Aug-2026; Rs3,000cr fresh; 2026 NCD issue is unrelated | Z32: https://www.chittorgarh.com/ipo/muthoot-fincorp-ipo/3219/
A33: 32 | B33: Zetwerk Manufacturing Businesses Limited | C33: 46248 | D33: 46248 | E33: UDRHP-I | F33: Confidential pre-filing (UDRHP-I published) | H33: DRHP filed — issue dates not announced | J33: 2600 | N33: 96837455 | O33: Fresh issue up to ₹2,600.00 Cr + OFS up to 96,837,455 sh | P33: Part of offer stated in ₹, rest in shares only (DRHP cover) — total depends on price band | Q33: https://www.sebi.gov.in/sebi_data/attachdocs/aug-2026/1786705255144.pdf | R33: https://www.sebi.gov.in/filings/public-issues/aug-2026/zetwerk-manufacturing-businesses-limited-udrhp_103643.html | S33: https://www.sebi.gov.in/sebi_data/commondocs/aug-2026/Zetwerk%20Manufacturing%20Businesses%20Limited%20-%20DAP_p.pdf | T33: 0 | X33: Dates not announced | Y33: SEBI nod Jul-2026; roadshows, targeting late Sep/mid-Oct; dates not yet announced | Z33: https://www.chittorgarh.com/ipo/zetwerk-ipo/3091/
A34: 33 | B34: Tonbo Imaging India Limited | C34: 46021 | D34: 46248 | E34: DRHP | F34: Regular DRHP | H34: DRHP filed — issue dates not announced | L34: 18085246 | M34: 18085246 | O34: Fresh issue up to 18,085,246 sh | P34: DRHP states number of shares only (DRHP cover) — ₹ size depends on price band | Q34: https://www.sebi.gov.in/sebi_data/attachdocs/aug-2026/1786692605529_1339.pdf | R34: https://www.sebi.gov.in/filings/public-issues/aug-2026/tonbo-imaging-india-limited-drhp_103625.html | S34: https://www.sebi.gov.in/sebi_data/commondocs/aug-2026/Tonbo%20Imaging%20India%20Limited%20-%20DAP_p.pdf | T34: 0 | X34: Dates not announced | Y34: SEBI nod Jun-2026; DRHP refiled Aug-2026; dates not announced | Z34: https://www.chittorgarh.com/ipo/tonbo-imaging-india-ipo/3215/
A35: 34 | B35: AGS Health Limited | C35: 46248 | D35: 46248 | E35: UDRHP-I | F35: Confidential pre-filing (UDRHP-I published) | H35: DRHP filed — issue dates not announced | O35: Not read — see DRHP PDF | P35: Offer terms not extracted — open the DRHP PDF | Q35: https://www.sebi.gov.in/sebi_data/attachdocs/aug-2026/1786684492213.pdf | R35: https://www.sebi.gov.in/filings/public-issues/aug-2026/ags-health-limited-udrhp_103617.html | S35: https://www.sebi.gov.in/sebi_data/commondocs/aug-2026/AGS%20Health%20Limited%20-%20AP_p.pdf | T35: 0 | X35: Dates not announced | Y35: SEBI nod Jun-2026; UDRHP-I Aug-2026; dates not announced | Z35: https://www.chittorgarh.com/ipo/ags-health-ipo/3093/
A36: 35 | B36: EAAA India Alternatives Limited | C36: 45636 | D36: 46247 | E36: DRHP | F36: Regular DRHP | H36: DRHP filed — issue dates not announced | I36: 1500 | K36: 1500 | O36: OFS up to ₹1,500.00 Cr | P36: ₹ amount stated in DRHP cover | Q36: https://www.sebi.gov.in/sebi_data/attachdocs/sep-2026/1789018300594.pdf | R36: https://www.sebi.gov.in/filings/public-issues/aug-2026/eaaa-india-alternatives-limited_104397.html | T36: 0 | X36: Dates not announced | Y36: SEBI nod Apr-2026; Rs1,500cr OFS; dates not announced | Z36: https://www.chittorgarh.com/ipo/eaaa-india-alternatives-ipo/2061/
A37: 36 | B37: J PAN TUBULAR COMPONENTS LIMITED | C37: 46246 | D37: 46246 | E37: DRHP | F37: Regular DRHP | H37: DRHP filed — issue dates not announced | L37: 5180000 | M37: 4920000 | N37: 260000 | O37: Fresh issue up to 4,920,000 sh + OFS up to 260,000 sh | P37: DRHP states number of shares only (DRHP cover) — ₹ size depends on price band | Q37: https://www.sebi.gov.in/sebi_data/attachdocs/aug-2026/1786519804294_1338.pdf | R37: https://www.sebi.gov.in/filings/public-issues/aug-2026/j-pan-tubular-components-limited-drhp_103499.html | S37: https://www.sebi.gov.in/sebi_data/commondocs/aug-2026/J%20PAN%20TUBULAR%20COMPONENTS%20LIMITED%20-%20DAP_p.pdf | T37: 0 | X37: Dates not announced | Y37: DRHP filed Jul/Aug-2026; dates not announced | Z37: https://www.chittorgarh.com/ipo/j-pan-tubular-components-ipo/3191/
A38: 37 | B38: BEAUTY GARAGE LIMITED | C38: 46245 | D38: 46245 | E38: DRHP | F38: Regular DRHP | H38: DRHP filed — issue dates not announced | J38: 125 | N38: 7836000 | O38: Fresh issue up to ₹125.00 Cr + OFS up to 7,836,000 sh | P38: Part of offer stated in ₹, rest in shares only (DRHP cover) — total depends on price band | Q38: https://www.sebi.gov.in/sebi_data/attachdocs/aug-2026/1786439399725.pdf | R38: https://www.sebi.gov.in/filings/public-issues/aug-2026/beauty-garage-limited-drhp_103479.html | S38: https://www.sebi.gov.in/sebi_data/commondocs/aug-2026/BEAUTY%20GARAGE%20LIMITED%20-%20AP_p.pdf | T38: 0 | X38: Dates not announced | Y38: DRHP filed 2026; Rs125cr fresh issue + OFS; dates not announced | Z38: https://www.chittorgarh.com/ipo/beauty-garage-ipo/3208/
A39: 38 | B39: Arjun Jewellers Limited | C39: 45936 | D39: 46244 | E39: DRHP | F39: Regular DRHP | H39: DRHP filed — issue dates not announced | I39: 200 | J39: 200 | O39: Fresh issue up to ₹200.00 Cr | P39: ₹ amount stated in DRHP cover | Q39: https://www.sebi.gov.in/sebi_data/attachdocs/aug-2026/1786357330303.pdf | R39: https://www.sebi.gov.in/filings/public-issues/aug-2026/arjun-jewellers-limited-drhp_103462.html | S39: https://www.sebi.gov.in/sebi_data/commondocs/aug-2026/Arjun%20Jewellers%20Limited%20-%20DAP_p.pdf | T39: 0 | X39: Dates not announced | Y39: Earlier DRHP withdrawn 12-Mar-2026; new draft Aug-2026; dates not announced | Z39: https://www.chittorgarh.com/ipo/arjun-jewellers-ipo/2741/
A40: 39 | B40: Encube Ethicals Limited | C40: 46240 | D40: 46240 | E40: DRHP | F40: Regular DRHP | H40: DRHP filed — issue dates not announced | O40: Not read — see DRHP PDF | P40: Offer terms not extracted — open the DRHP PDF | Q40: https://www.sebi.gov.in/sebi_data/attachdocs/aug-2026/1785994501228.pdf | R40: https://www.sebi.gov.in/filings/public-issues/aug-2026/encube-ethicals-limited-drhp_103383.html | S40: https://www.sebi.gov.in/sebi_data/commondocs/aug-2026/Encube%20Ethicals%20Limited%20-%20AP_p.pdf | T40: 0 | X40: Dates not announced | Y40: DRHP filed Aug-2026; Rs3,000cr OFS; reports say IPO likely by 2027 | Z40: https://www.chittorgarh.com/ipo/encube-ethicals-ipo/3211/
...

Sheet All DRHP Filings
A1: S.No | B1: Filing Date (SEBI) | C1: Filing Year | D1: IPO / Company Name | E1: Document Type | F1: Title as on SEBI | G1: IPO Status | H1: Segment | I1: IPO Issue (Open) Date | J1: IPO Close Date | K1: Listing Date | L1: IPO Size (₹ Cr) | M1: Fresh Issue (₹ Cr) | N1: OFS (₹ Cr) | O1: Size Basis | P1: Offer Terms per DRHP | Q1: DRHP / Document PDF (SEBI) | R1: SEBI Filing Page | S1: Draft Abridged Prospectus | T1: IPO Linked By | U1: IPO Name in Source | V1: Notes | W1: IPO Issue Open Date (web search) | X1: IPO Issue Close Date (web search) | Y1: Listing Date (web search) | Z1: Web Search Status | AA1: Web Search Note | AB1: Web Search Source
A2: 1 | B2: 46295 | C2: 2026 | D2: J B ECOTEX LIMITED | E2: DRHP | F2: J B ECOTEX LIMITED | G2: Upcoming — IPO not yet opened | Q2: https://www.sebi.gov.in/sebi_data/attachdocs/sep-2026/1790767812069_1378.pdf | R2: https://www.sebi.gov.in/filings/public-issues/sep-2026/j-b-ecotex-limited_104830.html | Z2: Dates not announced | AA2: DRHP filed; dates not announced | AB2: https://www.chittorgarh.com/ipo/j-b-ecotex-ipo/3311/
A3: 2 | B3: 46295 | C3: 2026 | D3: S G Encon Limited | E3: DRHP | F3: S G Encon Limited | G3: Upcoming — IPO not yet opened | O3: DRHP cover | P3: Fresh issue up to 7,190,400 sh + OFS up to 1,371,300 sh | Q3: https://www.sebi.gov.in/sebi_data/attachdocs/sep-2026/1790767812069_1377.pdf | R3: https://www.sebi.gov.in/filings/public-issues/sep-2026/s-g-encon-limited_104828.html | Z3: Dates not announced | AA3: DRHP filed; no IPO dates found
A4: 3 | B4: 46295 | C4: 2026 | D4: S. D. INTERNATIONAL LIMITED | E4: DRHP | F4: S. D. INTERNATIONAL LIMITED | G4: Upcoming — IPO not yet opened | Q4: https://www.sebi.gov.in/sebi_data/attachdocs/sep-2026/1790767812069_1376.pdf | R4: https://www.sebi.gov.in/filings/public-issues/sep-2026/s-d-international-limited_104826.html | Z4: Dates not announced | AA4: DRHP filed; no IPO dates found
A5: 4 | B5: 46294 | C5: 2026 | D5: ULTRAVIBRANT INTEGRATED ENERGY LIMITED | E5: DRHP | F5: ULTRAVIBRANT INTEGRATED ENERGY LIMITED | G5: Upcoming — IPO not yet opened | O5: DRHP cover | P5: Fresh issue up to 12,000,000 sh + OFS up to 2,500,000 sh | Q5: https://www.sebi.gov.in/sebi_data/attachdocs/sep-2026/1790681405842_1375.pdf | R5: https://www.sebi.gov.in/filings/public-issues/sep-2026/ultravibrant-integrated-energy-limited_104809.html | Z5: Dates not announced | AA5: DRHP filed; no IPO dates found
A6: 5 | B6: 46293 | C6: 2026 | D6: Iris Global Services Limited | E6: DRHP | F6: Iris Global Services Limited - DRHP | G6: Upcoming — IPO not yet opened | Q6: https://www.sebi.gov.in/sebi_data/attachdocs/sep-2026/1790743844411.pdf | R6: https://www.sebi.gov.in/filings/public-issues/sep-2026/iris-global-services-limited-drhp_104746.html | S6: https://www.sebi.gov.in/sebi_data/commondocs/sep-2026/Iris%20Global%20Services%20Limited%20-%20DAP_p.pdf | Z6: Dates not announced | AA6: DRHP filed; no IPO dates found
A7: 6 | B7: 46290 | C7: 2026 | D7: JSW One Platforms Limited | E7: DRHP | F7: JSW One Platforms Limited - DRHP | G7: Upcoming — IPO not yet opened | L7: 3054.01 | M7: 1300 | N7: 1754.01 | O7: DRHP cover | P7: Fresh issue up to ₹1,300.00 Cr + OFS up to ₹1,754.01 Cr | Q7: https://www.sebi.gov.in/sebi_data/attachdocs/sep-2026/1790585630648.pdf | R7: https://www.sebi.gov.in/filings/public-issues/sep-2026/jsw-one-platforms-limited-drhp_104742.html | S7: https://www.sebi.gov.in/sebi_data/commondocs/sep-2026/JSW%20One%20Platforms%20Limited%20-%20Draft%20Abridged%20Prospectus_p.pdf | Z7: Dates not announced | AA7: DRHP filed Sep-2026; dates not announced | AB7: https://www.chittorgarh.com/ipo/jsw-one-platform-ipo/3295/
A8: 7 | B8: 46290 | C8: 2026 | D8: Anjali Labtech Limited | E8: UDRHP-I | F8: Anjali Labtech Limited - UDRHP-I | G8: Upcoming — IPO not yet opened | Q8: https://www.sebi.gov.in/sebi_data/attachdocs/sep-2026/1790320604407.pdf | R8: https://www.sebi.gov.in/filings/public-issues/sep-2026/anjali-labtech-limited-udrhp-i_104737.html | S8: https://www.sebi.gov.in/sebi_data/commondocs/sep-2026/Anjali%20Labtech%20Limited%20-%20DAP_p.pdf | Z8: Dates not announced | AA8: SEBI nod Feb-2026; UDRHP-I filed Sep-2026; dates not announced | AB8: https://www.chittorgarh.com/ipo/anjali-labtech-ipo/2786/
A9: 8 | B9: 46287 | C9: 2026 | D9: VARDAAN BIOTECH LIMITED | E9: DRHP | F9: VARDAAN BIOTECH LIMITED - DRHP | G9: Upcoming — IPO not yet opened | Q9: https://www.sebi.gov.in/sebi_data/attachdocs/sep-2026/1790076604769_1355.pdf | R9: https://www.sebi.gov.in/filings/public-issues/sep-2026/vardaan-biotech-limited-drhp_104652.html | S9: https://www.sebi.gov.in/sebi_data/commondocs/sep-2026/VARDAAN%20BIOTECH%20LIMITED_p.pdf | Z9: Dates not announced | AA9: Refiled on mainboard; earlier SME DRHP withdrawn Jul-2024; no dates | AB9: https://www.barandbench.com/law-firms/dealstreet/legacy-law-offices-acts-on-vardaan-biotech-90-crore-ipo
A10: 9 | B10: 46287 | C10: 2026 | D10: Hi-Tech Flow Solutions Limited | E10: DRHP | F10: Hi-Tech Flow Solutions Limited - DRHP | G10: Upcoming — IPO not yet opened | Q10: https://www.sebi.gov.in/sebi_data/attachdocs/sep-2026/1790058959002.pdf | R10: https://www.sebi.gov.in/filings/public-issues/sep-2026/hi-tech-flow-solutions-limited-drhp_104635.html | S10: https://www.sebi.gov.in/sebi_data/commondocs/sep-2026/HitechFlowSolutionsDAP_p.pdf | Z10: Dates not announced | AA10: DRHP filed; no IPO dates found
A11: 10 | B11: 46283 | C11: 2026 | D11: ANCHOR OFFSHORE SERVICES LIMITED | E11: DRHP | F11: ANCHOR OFFSHORE SERVICES LIMITED - DRHP | G11: Upcoming — IPO not yet opened | O11: DRHP cover | P11: Fresh issue up to 6,400,000 sh + OFS up to 600,000 sh | Q11: https://www.sebi.gov.in/sebi_data/attachdocs/sep-2026/1789731006415_1354.pdf | R11: https://www.sebi.gov.in/filings/public-issues/sep-2026/anchor-offshore-services-limited-drhp_104580.html | S11: https://www.sebi.gov.in/sebi_data/commondocs/sep-2026/Anchor%20Offshore%20Services%20Limited-DA_p.pdf | Z11: Dates not announced | AA11: DRHP filed; no IPO dates found
A12: 11 | B12: 46283 | C12: 2026 | D12: Madhur Iron & Steel India Limited | E12: DRHP | F12: Madhur Iron & Steel India Limited - DRHP | G12: Upcoming — IPO not yet opened | Q12: https://www.sebi.gov.in/sebi_data/attachdocs/sep-2026/1789720399852.pdf | R12: https://www.sebi.gov.in/filings/public-issues/sep-2026/madhur-iron-and-steel-india-limited-drhp_104575.html | S12: https://www.sebi.gov.in/sebi_data/commondocs/sep-2026/Madhur%20Iron%20And%20Steel%20India%20Limited%20-%20Draft%20AP_p.pdf | Z12: Dates not announced | AA12: Earlier DRHP withdrawn Mar-2026; fresh DRHP Sep-2026; no IPO dates | AB12: https://www.chittorgarh.com/ipo/madhur-iron-and-steel-ipo/2855/
A13: 12 | B13: 46282 | C13: 2026 | D13: IBERIA PHARMACEUTICALS INDIA LIMITED | E13: DRHP | F13: IBERIA PHARMACEUTICALS INDIA LIMITED - DRHP | G13: Upcoming — IPO not yet opened | Q13: https://www.sebi.gov.in/sebi_data/attachdocs/sep-2026/1789635115853.pdf | R13: https://www.sebi.gov.in/filings/public-issues/sep-2026/iberia-pharmaceuticals-india-limited-drhp_104542.html | S13: https://www.sebi.gov.in/sebi_data/commondocs/sep-2026/IBERIA%20PHARMACEUTICALS%20INDIA%20LIMITED_p.pdf | Z13: Dates not announced | AA13: DRHP filed; no IPO dates found
A14: 13 | B14: 46282 | C14: 2026 | D14: Rayzon Solar Limited | E14: Addendum | F14: Rayzon Solar Limited - Addendum to the DRHP | G14: Upcoming — IPO not yet opened | Q14: https://www.sebi.gov.in/sebi_data/attachdocs/sep-2026/1789624666577.pdf | R14: https://www.sebi.gov.in/filings/public-issues/sep-2026/rayzon-solar-limited-addendum-to-the-drhp_104532.html | Z14: Dates not announced | AA14: SEBI nod 13-Oct-2025 (valid till Oct-2026); dates not announced | AB14: https://www.chittorgarh.com/ipo/rayzon-solar-ipo/2490/
A15: 14 | B15: 46281 | C15: 2026 | D15: Sterlite Electric Limited | E15: Addendum | F15: Sterlite Electric Limited – Second Addendum to DRHP | G15: Upcoming — IPO not yet opened | Q15: https://www.sebi.gov.in/sebi_data/attachdocs/sep-2026/1789549247423.pdf | R15: https://www.sebi.gov.in/filings/public-issues/sep-2026/sterlite-electric-limited-second-addendum-to-drhp_104506.html | Z15: Dates not announced | AA15: DRHP filed; dates, price band not yet announced | AB15: https://www.chittorgarh.com/ipo/sterlite-electric-ipo/2679/
A16: 15 | B16: 46280 | C16: 2026 | D16: Maharashtra Oil Extractions Limited | E16: DRHP | F16: Maharashtra Oil Extractions Limited - DRHP | G16: Upcoming — IPO not yet opened | Q16: https://www.sebi.gov.in/sebi_data/attachdocs/sep-2026/1789531323564.pdf | R16: https://www.sebi.gov.in/filings/public-issues/sep-2026/maharashtra-oil-extractions-limited-drhp_104503.html | S16: https://www.sebi.gov.in/sebi_data/commondocs/sep-2026/Maharashtra%20Oil%20Extractions%20Limited%20-%20DAP_p.pdf | Z16: Dates not announced | AA16: DRHP filed; no IPO dates found
A17: 16 | B17: 46277 | C17: 2026 | D17: German Green Steel and Power Limited | E17: Addendum | F17: German Green Steel and Power Limited - Addendum II to DRHP | G17: Upcoming — IPO not yet opened | Q17: https://www.sebi.gov.in/sebi_data/attachdocs/sep-2026/1789448460012.pdf | R17: https://www.sebi.gov.in/filings/public-issues/sep-2026/german-green-steel-and-power-limited-addendum-ii-to-drhp_104480.html | W17: 46290 | X17: 46294 | Y17: 46300 | Z17: Issue closed — listing pending | AA17: Price band Rs132-139; subscribed 30.4x; listing 5-Oct-2026 tentative | AB17: https://www.chittorgarh.com/ipo/german-green-steel-and-power-ipo/2497/
A18: 17 | B18: 46276 | C18: 2026 | D18: M K C AGRO FRESH LIMITED | E18: DRHP | F18: M K C AGRO FRESH LIMITED - DRHP | G18: Upcoming — IPO not yet opened | O18: DRHP cover | P18: Fresh issue up to 9,999,000 sh + OFS up to 6,811,751 sh | Q18: https://www.sebi.gov.in/sebi_data/attachdocs/sep-2026/1789111806400_1350.pdf | R18: https://www.sebi.gov.in/filings/public-issues/sep-2026/m-k-c-agro-fresh-limited-drhp_104430.html | S18: https://www.sebi.gov.in/sebi_data/commondocs/sep-2026/M%20K%20C%20AGRO%20FRESH%20LIMITED%20-%20DAP_p.pdf | Z18: Dates not announced | AA18: DRHP filed; no IPO dates found
A19: 18 | B19: 46276 | C19: 2026 | D19: NOPAPERFORMS SOLUTIONS LIMITED | E19: UDRHP-I | F19: NOPAPERFORMS SOLUTIONS LIMITED - UDRHP-1 | G19: Upcoming — IPO not yet opened | M19: 375 | O19: DRHP cover | P19: Fresh issue up to ₹375.00 Cr + OFS up to 38,422,392 sh | Q19: https://www.sebi.gov.in/sebi_data/attachdocs/sep-2026/1789104761658.pdf | R19: https://www.sebi.gov.in/filings/public-issues/sep-2026/nopaperforms-solutions-limited-udrhp-1_104427.html | S19: https://www.sebi.gov.in/sebi_data/commondocs/sep-2026/NOPAPERFORMS%20SOLUTIONS%20LIMITED%20-%20DAP_p.pdf | Z19: Dates not announced | AA19: SEBI nod Mar-2026; UDRHP-I filed Sep-2026; dates not announced | AB19: https://www.chittorgarh.com/ipo/nopaperforms-solutions-ipo/2796/
A20: 19 | B20: 46276 | C20: 2026 | D20: RUNWAL ENTERPRISES LIMITED | E20: Addendum | F20: RUNWAL ENTERPRISES LIMITED - Addendum to DRHP | G20: Upcoming — IPO not yet opened | Q20: https://www.sebi.gov.in/sebi_data/attachdocs/sep-2026/1789099604614.pdf | R20: https://www.sebi.gov.in/filings/public-issues/sep-2026/runwal-enterprises-limited-addendum-to-drhp_104424.html | W20: 46290 | X20: 46294 | Y20: 46300 | Z20: Issue opened | AA20: Matched on chittorgarh.com | AB20: https://www.chittorgarh.com/ipo/runwal-enterprises-ipo/2298/
A21: 20 | B21: 46275 | C21: 2026 | D21: Incred Holdings Limited | E21: Corrigendum | F21: Incred Holdings Limited - Corrigendum to UDRHP | G21: Upcoming — IPO not yet opened | Q21: https://www.sebi.gov.in/sebi_data/attachdocs/sep-2026/1789618323211.pdf | R21: https://www.sebi.gov.in/filings/public-issues/sep-2026/incred-holdings-limited-corrigendum-to-udrhp_104399.html | Z21: Dates not announced | AA21: SEBI nod 5-Feb-2026; UDRHP-I filed; dates not announced | AB21: https://www.chittorgarh.com/ipo/incred-holdings-ipo/2797/
A22: 21 | B22: 46274 | C22: 2026 | D22: Torrent Gas Limited | E22: UDRHP-I | F22: Torrent Gas Limited - UDRHP-I | G22: Upcoming — IPO not yet opened | O22: DRHP cover | P22: OFS up to 335,000,000 sh | Q22: https://www.sebi.gov.in/sebi_data/attachdocs/sep-2026/1788937260208.PDF | R22: https://www.sebi.gov.in/filings/public-issues/sep-2026/torrent-gas-limited-udrhp-i_104350.html | S22: https://www.sebi.gov.in/sebi_data/commondocs/sep-2026/Torrent%20Gas%20Limited%20-%20DAP_p.pdf | Z22: Dates not announced | AA22: Confidential filing cleared Jun-2026; UDRHP-I Sep-2026; dates not announced | AB22: https://ipowatch.in/torrent-gas-ipo/
A23: 22 | B23: 46273 | C23: 2026 | D23: Hero Motors Limited | E23: Addendum cum Corrigendum | F23: Hero Motors Limited - Corrigendum to Addendum. | G23: IPO launched | H23: Mainboard | I23: 46281 | J23: 46283 | K23: 46288 | L23: 1000 | M23: 600 | N23: 400 | O23: Final issue (ipoplatform) | Q23: https://www.sebi.gov.in/sebi_data/attachdocs/sep-2026/1788844179347.pdf | R23: https://www.sebi.gov.in/filings/public-issues/sep-2026/hero-motors-limited-corrigendum-to-addendum-_104330.html | T23: Company name + date window | U23: Hero Motors Limited
A24: 23 | B24: 46269 | C24: 2026 | D24: Mahanadi Coalfields Ltd | E24: DRHP | F24: Mahanadi Coalfields Ltd. - DRHP | G24: Upcoming — IPO not yet opened | Q24: https://www.sebi.gov.in/sebi_data/attachdocs/sep-2026/1788761365481.pdf | R24: https://www.sebi.gov.in/filings/public-issues/sep-2026/mahanadi-coalfields-ltd-drhp_104290.html | S24: https://www.sebi.gov.in/sebi_data/commondocs/sep-2026/Mahanadi%20Coalfields%20Limited%20_Draft%20Abridged%20Prospectus_p.pdf | Z24: Dates not announced | AA24: DRHP filed; dates not announced | AB24: https://www.chittorgarh.com/ipo/mahanadi-coalfields-ipo/3247/
A25: 24 | B25: 46269 | C25: 2026 | D25: Gaurik Fashions Limited | E25: Addendum | F25: Gaurik Fashions Limited - Addendum to DRHP | G25: Upcoming — IPO not yet opened | Q25: https://www.sebi.gov.in/sebi_data/attachdocs/sep-2026/1788516638656.pdf | R25: https://www.sebi.gov.in/filings/public-issues/sep-2026/gaurik-fashions-limited-addendum-to-drhp_104276.html | Z25: Dates not announced | AA25: SEBI approval pending; dates not announced | AB25: https://www.chittorgarh.com/ipo/gaurik-fashions-ipo/3098/
A26: 25 | B26: 46269 | C26: 2026 | D26: India Exposition Mart Limited | E26: DRHP | F26: India Exposition Mart Limited | G26: Upcoming — IPO not yet opened | Q26: https://www.sebi.gov.in/sebi_data/attachdocs/sep-2026/1788507005445_1348.pdf | R26: https://www.sebi.gov.in/filings/public-issues/sep-2026/india-exposition-mart-limited_104273.html | Z26: Dates not announced | AA26: Refiled DRHP 2026; dates not announced | AB26: https://www.chittorgarh.com/ipo/india-exposition-mart-ipo/3225/
A27: 26 | B27: 46266 | C27: 2026 | D27: Kataria Dhulchand Pannalal Jewellers Limited | E27: DRHP | F27: Kataria Dhulchand Pannalal Jewellers Limited - DRHP | G27: Upcoming — IPO not yet opened | O27: DRHP cover | P27: Fresh issue up to 16,000,000 sh | Q27: https://www.sebi.gov.in/sebi_data/attachdocs/sep-2026/1788262207109_1345.pdf | R27: https://www.sebi.gov.in/filings/public-issues/sep-2026/kataria-dhulchand-pannalal-jewellers-limited-drhp_104178.html | S27: https://www.sebi.gov.in/sebi_data/commondocs/sep-2026/Kataria%20Dhulchand%20Pannalal%20Jewellers%20Ltd%20-%20DAP_p.pdf | Z27: Dates not announced | AA27: DRHP filed; no IPO dates found
A28: 27 | B28: 46266 | C28: 2026 | D28: Sembcorp Green Infra Limited | E28: DRHP | F28: Sembcorp Green Infra Limited - DRHP | G28: Upcoming — IPO not yet opened | L28: 3750 | M28: 3750 | O28: DRHP cover | P28: Fresh issue up to ₹3,750.00 Cr | Q28: https://www.sebi.gov.in/sebi_data/attachdocs/sep-2026/1788245484072.pdf | R28: https://www.sebi.gov.in/filings/public-issues/sep-2026/sembcorp-green-infra-limited-drhp_104162.html | S28: https://www.sebi.gov.in/sebi_data/commondocs/sep-2026/Sembcorp%20Green%20Infra%20Limited%20-%20Draft%20Abridged%20Prospectus_p.pdf | Z28: Dates not announced | AA28: DRHP filed Aug/Sep-2026; dates not announced | AB28: https://www.chittorgarh.com/ipo/sembcorp-green-infra-ipo/3240/
A29: 28 | B29: 46266 | C29: 2026 | D29: ARAGEN LIFE SCIENCES LIMITED | E29: DRHP | F29: ARAGEN LIFE SCIENCES LIMITED - DRHP | G29: Upcoming — IPO not yet opened | Q29: https://www.sebi.gov.in/sebi_data/attachdocs/sep-2026/1788238496589.pdf | R29: https://www.sebi.gov.in/filings/public-issues/sep-2026/aragen-life-sciences-limited-drhp_104157.html | S29: https://www.sebi.gov.in/sebi_data/commondocs/sep-2026/ARAGEN%20LIFE%20SCIENCES%20LIMITED%20-%20DAP_p.pdf | Z29: Dates not announced | AA29: DRHP filed Aug-2026; IPO dates not announced | AB29: https://ipowatch.in/aragen-life-sciences-ipo/
A30: 29 | B30: 46265 | C30: 2026 | D30: HERO MOTORS LIMITED | E30: Addendum | F30: HERO MOTORS LIMITED - Addendum to DRHP | G30: IPO launched | H30: Mainboard | I30: 46281 | J30: 46283 | K30: 46288 | L30: 1000 | M30: 600 | N30: 400 | O30: Final issue (ipoplatform) | Q30: https://www.sebi.gov.in/sebi_data/attachdocs/aug-2026/1788154946517.PDF | R30: https://www.sebi.gov.in/filings/public-issues/aug-2026/hero-motors-limited-addendum-to-drhp_104121.html | T30: Company name + date window | U30: Hero Motors Limited
A31: 30 | B31: 46261 | C31: 2026 | D31: ATOMBERG TECHNOLOGIES LIMITED | E31: DRHP | F31: ATOMBERG TECHNOLOGIES LIMITED - DRHP | G31: Upcoming — IPO not yet opened | M31: 450 | O31: DRHP cover | P31: Fresh issue up to ₹450.00 Cr + OFS up to 76,541,851 sh | Q31: https://www.sebi.gov.in/sebi_data/attachdocs/aug-2026/1787809930622.pdf | R31: https://www.sebi.gov.in/filings/public-issues/aug-2026/atomberg-technologies-limited-drhp_104037.html | S31: https://www.sebi.gov.in/sebi_data/commondocs/aug-2026/ATOMBERG%20TECHNOLOGIES%20LIMITED%20-%20AP_p.pdf | Z31: Dates not announced | AA31: DRHP filed Aug-2026; Rs450cr fresh + OFS; dates not announced | AB31: https://www.chittorgarh.com/ipo/atomberg-technologies-ipo/3227/
A32: 31 | B32: 46261 | C32: 2026 | D32: KARAMTARA ENGINEERING LIMITED | E32: Addendum | F32: KARAMTARA ENGINEERING LIMITED - Addendum to DRHP | G32: IPO launched | H32: Mainboard | I32: 46274 | J32: 46276 | K32: 46282 | L32: 875 | M32: 675 | N32: 200 | O32: Final issue (ipoplatform) | Q32: https://www.sebi.gov.in/sebi_data/attachdocs/aug-2026/1787804373286.pdf | R32: https://www.sebi.gov.in/filings/public-issues/aug-2026/karamtara-engineering-limited-addendum-to-drhp_104033.html | T32: Company name + date window | U32: Karamtara Engineering Limited
A33: 32 | B33: 46259 | C33: 2026 | D33: ArMee Infotech Limited | E33: Addendum | F33: ArMee Infotech Limited - Addendum II to DRHP | G33: IPO launched | H33: Mainboard | I33: 46288 | J33: 46290 | K33: 46295 | L33: 300 | M33: 300 | N33: 0 | O33: Final issue (ipoplatform) | Q33: https://www.sebi.gov.in/sebi_data/attachdocs/sep-2026/1788764099334.pdf | R33: https://www.sebi.gov.in/filings/public-issues/aug-2026/armee-infotech-limited-addendum-ii-to-drhp_104294.html | T33: Company name + date window | U33: ArMee Infotech Limited
A34: 33 | B34: 46259 | C34: 2026 | D34: AVAADA ELECTRO LIMITED | E34: UDRHP-I | F34: AVAADA ELECTRO LIMITED - UDRHP | G34: Upcoming — IPO not yet opened | Q34: https://www.sebi.gov.in/sebi_data/attachdocs/aug-2026/1787804677669.pdf | R34: https://www.sebi.gov.in/filings/public-issues/aug-2026/avaada-electro-limited-udrhp_104034.html | S34: https://www.sebi.gov.in/sebi_data/commondocs/aug-2026/Avaada%20Electro%20Limited%20-%20Draft%20Abridged%20Prospectus_p.pdf | Z34: Dates not announced | AA34: SEBI nod Apr-2026; Rs7,600cr; dates not announced | AB34: https://www.chittorgarh.com/ipo/avaada-electro-ipo/2790/
A35: 34 | B35: 46259 | C35: 2026 | D35: M P STEEL (INDIA) LIMITED | E35: DRHP | F35: M P STEEL (INDIA) LIMITED - DRHP | G35: Upcoming — IPO not yet opened | Q35: https://www.sebi.gov.in/sebi_data/attachdocs/aug-2026/1787653298920.pdf | R35: https://www.sebi.gov.in/filings/public-issues/aug-2026/m-p-steel-india-limited-drhp_103990.html | S35: https://www.sebi.gov.in/sebi_data/commondocs/aug-2026/MPSteel-Draft%20Abridged%20Prospectus_p.pdf | Z35: Dates not announced | AA35: DRHP filed Aug-2026; dates not announced (not MPK Steels SME) | AB35: https://www.chittorgarh.com/ipo/m-p-steel-ipo/3229/
A36: 35 | B36: 46259 | C36: 2026 | D36: Nobel Hygiene Limited | E36: DRHP | F36: Nobel Hygiene Limited - DRHP | G36: Upcoming — IPO not yet opened | Q36: https://www.sebi.gov.in/sebi_data/attachdocs/aug-2026/1787650339639.pdf | R36: https://www.sebi.gov.in/filings/public-issues/aug-2026/nobel-hygiene-limited-drhp_103938.html | S36: https://www.sebi.gov.in/sebi_data/commondocs/aug-2026/Nobel%20Hygiene%20Limited%20-%20Draft%20Abridged%20Prospectus_p.pdf | Z36: Dates not announced | AA36: DRHP filed Aug-2026; dates not announced | AB36: https://www.kotakneo.com/news/ipos/nobel-hygiene-files-drhp-for-rs-150-crore-ipo-after-profit-jumps-nearly-100-fold-in-fy26/
A37: 36 | B37: 46259 | C37: 2026 | D37: JAY JAGDAMBA LIMITED | E37: UDRHP-I | F37: JAY JAGDAMBA LIMITED - UDRHP | G37: Upcoming — IPO not yet opened | M37: 600 | O37: DRHP cover | P37: Fresh issue up to ₹600.00 Cr + OFS up to 15,000,000 sh | Q37: https://www.sebi.gov.in/sebi_data/attachdocs/aug-2026/1787637173016.pdf | R37: https://www.sebi.gov.in/filings/public-issues/aug-2026/jay-jagdamba-limited-udrhp_103937.html | S37: https://www.sebi.gov.in/sebi_data/commondocs/aug-2026/Jay%20Jagdamba%20Limited%20Draft%20Abridged%20Prospectus_p.pdf | Z37: Dates not announced | AA37: SEBI nod Jan-2026; UDRHP-I Aug-2026; dates not announced | AB37: https://www.chittorgarh.com/ipo/jay-jagdamba-ipo/2528/
A38: 37 | B38: 46258 | C38: 2026 | D38: T.C. Terrytex Limited | E38: Addendum cum Corrigendum | F38: T.C. Terrytex Limited - Addendum-cum-Corrigendum to DRHP | G38: Upcoming — IPO not yet opened | Q38: https://www.sebi.gov.in/sebi_data/attachdocs/aug-2026/1787564691044.pdf | R38: https://www.sebi.gov.in/filings/public-issues/aug-2026/t-c-terrytex-limited-addendum-cum-corrigendum-to-drhp_103904.html | Z38: Dates not announced | AA38: DRHP filed; no approval or dates announced | AB38: https://www.chittorgarh.com/ipo/tc-terrytex-ipo/2994/
A39: 38 | B39: 46256 | C39: 2026 | D39: GEMINI EDIBLES & FATS INDIA LIMITED | E39: DRHP | F39: GEMINI EDIBLES & FATS INDIA LIMITED - DRHP | G39: Upcoming — IPO not yet opened | Q39: https://www.sebi.gov.in/sebi_data/attachdocs/aug-2026/1787803545833.pdf | R39: https://www.sebi.gov.in/filings/public-issues/aug-2026/gemini-edibles-and-fats-india-limited-drhp_104032.html | S39: https://www.sebi.gov.in/sebi_data/commondocs/aug-2026/Gemini%20Edibles%20&%20Fats%20India%20Ltd.%20-%20Draft%20Abridged%20Prospectus_p.pdf | Z39: Dates not announced | AA39: 2021 DRHP was put in abeyance; refiled Aug-2026; dates not announced | AB39: https://www.chittorgarh.com/ipo/gemini-edibles-fats-india-ipo/3238/
A40: 39 | B40: 46255 | C40: 2026 | D40: Avtar Steel Limited | E40: DRHP | F40: Avtar Steel Limited - DRHP | G40: Upcoming — IPO not yet opened | Q40: https://www.sebi.gov.in/sebi_data/attachdocs/aug-2026/1787311805039_1343.pdf | R40: https://www.sebi.gov.in/filings/public-issues/aug-2026/avtar-steel-limited-drhp_103867.html | S40: https://www.sebi.gov.in/sebi_data/commondocs/aug-2026/Avtar%20Steel%20Limited%20-%20Draft%20Abridged%20Prospectus_p.pdf | Z40: Dates not announced | AA40: DRHP filed Aug-2026; Rs585cr fresh issue; dates not announced | AB40: https://www.businesstoday.in/markets/ipo-corner/story/avtar-steel-files-draft-ipo-papers-with-sebi-to-raise-rs-585-crore-through-fresh-issue-549604-2026-08-17
...

Sheet Summary
A1: Filing Year | B1: All Filings | C1: DRHP | D1: UDRHP-I | E1: Addenda / Corrigenda / Other | F1: Linked to Launched IPO | G1: Upcoming — Not Yet Opened | H1: No Launched IPO Found
A2: 2026 | B2: =COUNTIFS('All DRHP Filings'!$C$2:$C$2221,$A2) | C2: =COUNTIFS('All DRHP Filings'!$C$2:$C$2221,$A2,'All DRHP Filings'!$E$2:$E$2221,"DRHP") | D2: =COUNTIFS('All DRHP Filings'!$C$2:$C$2221,$A2,'All DRHP Filings'!$E$2:$E$2221,"UDRHP-I") | E2: =B2-C2-D2 | F2: =COUNTIFS('All DRHP Filings'!$C$2:$C$2221,$A2,'All DRHP Filings'!$G$2:$G$2221,"IPO launched") | G2: =COUNTIFS('All DRHP Filings'!$C$2:$C$2221,$A2,'All DRHP Filings'!$G$2:$G$2221,"Upcoming*") | H2: =COUNTIFS('All DRHP Filings'!$C$2:$C$2221,$A2,'All DRHP Filings'!$G$2:$G$2221,"No launched*")
A3: 2025 | B3: =COUNTIFS('All DRHP Filings'!$C$2:$C$2221,$A3) | C3: =COUNTIFS('All DRHP Filings'!$C$2:$C$2221,$A3,'All DRHP Filings'!$E$2:$E$2221,"DRHP") | D3: =COUNTIFS('All DRHP Filings'!$C$2:$C$2221,$A3,'All DRHP Filings'!$E$2:$E$2221,"UDRHP-I") | E3: =B3-C3-D3 | F3: =COUNTIFS('All DRHP Filings'!$C$2:$C$2221,$A3,'All DRHP Filings'!$G$2:$G$2221,"IPO launched") | G3: =COUNTIFS('All DRHP Filings'!$C$2:$C$2221,$A3,'All DRHP Filings'!$G$2:$G$2221,"Upcoming*") | H3: =COUNTIFS('All DRHP Filings'!$C$2:$C$2221,$A3,'All DRHP Filings'!$G$2:$G$2221,"No launched*")
A4: 2024 | B4: =COUNTIFS('All DRHP Filings'!$C$2:$C$2221,$A4) | C4: =COUNTIFS('All DRHP Filings'!$C$2:$C$2221,$A4,'All DRHP Filings'!$E$2:$E$2221,"DRHP") | D4: =COUNTIFS('All DRHP Filings'!$C$2:$C$2221,$A4,'All DRHP Filings'!$E$2:$E$2221,"UDRHP-I") | E4: =B4-C4-D4 | F4: =COUNTIFS('All DRHP Filings'!$C$2:$C$2221,$A4,'All DRHP Filings'!$G$2:$G$2221,"IPO launched") | G4: =COUNTIFS('All DRHP Filings'!$C$2:$C$2221,$A4,'All DRHP Filings'!$G$2:$G$2221,"Upcoming*") | H4: =COUNTIFS('All DRHP Filings'!$C$2:$C$2221,$A4,'All DRHP Filings'!$G$2:$G$2221,"No launched*")
A5: 2023 | B5: =COUNTIFS('All DRHP Filings'!$C$2:$C$2221,$A5) | C5: =COUNTIFS('All DRHP Filings'!$C$2:$C$2221,$A5,'All DRHP Filings'!$E$2:$E$2221,"DRHP") | D5: =COUNTIFS('All DRHP Filings'!$C$2:$C$2221,$A5,'All DRHP Filings'!$E$2:$E$2221,"UDRHP-I") | E5: =B5-C5-D5 | F5: =COUNTIFS('All DRHP Filings'!$C$2:$C$2221,$A5,'All DRHP Filings'!$G$2:$G$2221,"IPO launched") | G5: =COUNTIFS('All DRHP Filings'!$C$2:$C$2221,$A5,'All DRHP Filings'!$G$2:$G$2221,"Upcoming*") | H5: =COUNTIFS('All DRHP Filings'!$C$2:$C$2221,$A5,'All DRHP Filings'!$G$2:$G$2221,"No launched*")
A6: 2022 | B6: =COUNTIFS('All DRHP Filings'!$C$2:$C$2221,$A6) | C6: =COUNTIFS('All DRHP Filings'!$C$2:$C$2221,$A6,'All DRHP Filings'!$E$2:$E$2221,"DRHP") | D6: =COUNTIFS('All DRHP Filings'!$C$2:$C$2221,$A6,'All DRHP Filings'!$E$2:$E$2221,"UDRHP-I") | E6: =B6-C6-D6 | F6: =COUNTIFS('All DRHP Filings'!$C$2:$C$2221,$A6,'All DRHP Filings'!$G$2:$G$2221,"IPO launched") | G6: =COUNTIFS('All DRHP Filings'!$C$2:$C$2221,$A6,'All DRHP Filings'!$G$2:$G$2221,"Upcoming*") | H6: =COUNTIFS('All DRHP Filings'!$C$2:$C$2221,$A6,'All DRHP Filings'!$G$2:$G$2221,"No launched*")
A7: 2021 | B7: =COUNTIFS('All DRHP Filings'!$C$2:$C$2221,$A7) | C7: =COUNTIFS('All DRHP Filings'!$C$2:$C$2221,$A7,'All DRHP Filings'!$E$2:$E$2221,"DRHP") | D7: =COUNTIFS('All DRHP Filings'!$C$2:$C$2221,$A7,'All DRHP Filings'!$E$2:$E$2221,"UDRHP-I") | E7: =B7-C7-D7 | F7: =COUNTIFS('All DRHP Filings'!$C$2:$C$2221,$A7,'All DRHP Filings'!$G$2:$G$2221,"IPO launched") | G7: =COUNTIFS('All DRHP Filings'!$C$2:$C$2221,$A7,'All DRHP Filings'!$G$2:$G$2221,"Upcoming*") | H7: =COUNTIFS('All DRHP Filings'!$C$2:$C$2221,$A7,'All DRHP Filings'!$G$2:$G$2221,"No launched*")
A8: 2020 | B8: =COUNTIFS('All DRHP Filings'!$C$2:$C$2221,$A8) | C8: =COUNTIFS('All DRHP Filings'!$C$2:$C$2221,$A8,'All DRHP Filings'!$E$2:$E$2221,"DRHP") | D8: =COUNTIFS('All DRHP Filings'!$C$2:$C$2221,$A8,'All DRHP Filings'!$E$2:$E$2221,"UDRHP-I") | E8: =B8-C8-D8 | F8: =COUNTIFS('All DRHP Filings'!$C$2:$C$2221,$A8,'All DRHP Filings'!$G$2:$G$2221,"IPO launched") | G8: =COUNTIFS('All DRHP Filings'!$C$2:$C$2221,$A8,'All DRHP Filings'!$G$2:$G$2221,"Upcoming*") | H8: =COUNTIFS('All DRHP Filings'!$C$2:$C$2221,$A8,'All DRHP Filings'!$G$2:$G$2221,"No launched*")
A9: 2019 | B9: =COUNTIFS('All DRHP Filings'!$C$2:$C$2221,$A9) | C9: =COUNTIFS('All DRHP Filings'!$C$2:$C$2221,$A9,'All DRHP Filings'!$E$2:$E$2221,"DRHP") | D9: =COUNTIFS('All DRHP Filings'!$C$2:$C$2221,$A9,'All DRHP Filings'!$E$2:$E$2221,"UDRHP-I") | E9: =B9-C9-D9 | F9: =COUNTIFS('All DRHP Filings'!$C$2:$C$2221,$A9,'All DRHP Filings'!$G$2:$G$2221,"IPO launched") | G9: =COUNTIFS('All DRHP Filings'!$C$2:$C$2221,$A9,'All DRHP Filings'!$G$2:$G$2221,"Upcoming*") | H9: =COUNTIFS('All DRHP Filings'!$C$2:$C$2221,$A9,'All DRHP Filings'!$G$2:$G$2221,"No launched*")
A10: 2018 | B10: =COUNTIFS('All DRHP Filings'!$C$2:$C$2221,$A10) | C10: =COUNTIFS('All DRHP Filings'!$C$2:$C$2221,$A10,'All DRHP Filings'!$E$2:$E$2221,"DRHP") | D10: =COUNTIFS('All DRHP Filings'!$C$2:$C$2221,$A10,'All DRHP Filings'!$E$2:$E$2221,"UDRHP-I") | E10: =B10-C10-D10 | F10: =COUNTIFS('All DRHP Filings'!$C$2:$C$2221,$A10,'All DRHP Filings'!$G$2:$G$2221,"IPO launched") | G10: =COUNTIFS('All DRHP Filings'!$C$2:$C$2221,$A10,'All DRHP Filings'!$G$2:$G$2221,"Upcoming*") | H10: =COUNTIFS('All DRHP Filings'!$C$2:$C$2221,$A10,'All DRHP Filings'!$G$2:$G$2221,"No launched*")
A11: 2017 | B11: =COUNTIFS('All DRHP Filings'!$C$2:$C$2221,$A11) | C11: =COUNTIFS('All DRHP Filings'!$C$2:$C$2221,$A11,'All DRHP Filings'!$E$2:$E$2221,"DRHP") | D11: =COUNTIFS('All DRHP Filings'!$C$2:$C$2221,$A11,'All DRHP Filings'!$E$2:$E$2221,"UDRHP-I") | E11: =B11-C11-D11 | F11: =COUNTIFS('All DRHP Filings'!$C$2:$C$2221,$A11,'All DRHP Filings'!$G$2:$G$2221,"IPO launched") | G11: =COUNTIFS('All DRHP Filings'!$C$2:$C$2221,$A11,'All DRHP Filings'!$G$2:$G$2221,"Upcoming*") | H11: =COUNTIFS('All DRHP Filings'!$C$2:$C$2221,$A11,'All DRHP Filings'!$G$2:$G$2221,"No launched*")
A12: 2016 | B12: =COUNTIFS('All DRHP Filings'!$C$2:$C$2221,$A12) | C12: =COUNTIFS('All DRHP Filings'!$C$2:$C$2221,$A12,'All DRHP Filings'!$E$2:$E$2221,"DRHP") | D12: =COUNTIFS('All DRHP Filings'!$C$2:$C$2221,$A12,'All DRHP Filings'!$E$2:$E$2221,"UDRHP-I") | E12: =B12-C12-D12 | F12: =COUNTIFS('All DRHP Filings'!$C$2:$C$2221,$A12,'All DRHP Filings'!$G$2:$G$2221,"IPO launched") | G12: =COUNTIFS('All DRHP Filings'!$C$2:$C$2221,$A12,'All DRHP Filings'!$G$2:$G$2221,"Upcoming*") | H12: =COUNTIFS('All DRHP Filings'!$C$2:$C$2221,$A12,'All DRHP Filings'!$G$2:$G$2221,"No launched*")
A13: 2015 | B13: =COUNTIFS('All DRHP Filings'!$C$2:$C$2221,$A13) | C13: =COUNTIFS('All DRHP Filings'!$C$2:$C$2221,$A13,'All DRHP Filings'!$E$2:$E$2221,"DRHP") | D13: =COUNTIFS('All DRHP Filings'!$C$2:$C$2221,$A13,'All DRHP Filings'!$E$2:$E$2221,"UDRHP-I") | E13: =B13-C13-D13 | F13: =COUNTIFS('All DRHP Filings'!$C$2:$C$2221,$A13,'All DRHP Filings'!$G$2:$G$2221,"IPO launched") | G13: =COUNTIFS('All DRHP Filings'!$C$2:$C$2221,$A13,'All DRHP Filings'!$G$2:$G$2221,"Upcoming*") | H13: =COUNTIFS('All DRHP Filings'!$C$2:$C$2221,$A13,'All DRHP Filings'!$G$2:$G$2221,"No launched*")
... A24: 2004 | B24: =COUNTIFS('All DRHP Filings'!$C$2:$C$2221,$A24) | C24: =COUNTIFS('All DRHP Filings'!$C$2:$C$2221,$A24,'All DRHP Filings'!$E$2:$E$2221,"DRHP") | D24: =COUNTIFS('All DRHP Filings'!$C$2:$C$2221,$A24,'All DRHP Filings'!$E$2:$E$2221,"UDRHP-I") | E24: =B24-C24-D24 | F24: =COUNTIFS('All DRHP Filings'!$C$2:$C$2221,$A24,'All DRHP Filings'!$G$2:$G$2221,"IPO launched") | G24: =COUNTIFS('All DRHP Filings'!$C$2:$C$2221,$A24,'All DRHP Filings'!$G$2:$G$2221,"Upcoming*") | H24: =COUNTIFS('All DRHP Filings'!$C$2:$C$2221,$A24,'All DRHP Filings'!$G$2:$G$2221,"No launched*")
A25: TOTAL | B25: =SUM(B2:B24) | C25: =SUM(C2:C24) | D25: =SUM(D2:D24) | E25: =SUM(E2:E24) | F25: =SUM(F2:F24) | G25: =SUM(G2:G24) | H25: =SUM(H2:H24)

Sheet Source & Notes
A1: SEBI draft offer documents — upcoming IPO pipeline and full filing register
A3: Source page | B3: SEBI > Filings > Public Issues > Draft Offer Documents filed with SEBI — https://www.sebi.gov.in/sebiweb/home/HomeAction.do?doListing=yes&sid=3&ssid=15&smid=10
A4: Coverage | B4: All 2,220 entries on that page, 08-Jun-2004 to 30-Sep-2026: 1,988 DRHP, 135 Addendum, 45 Corrigendum, 27 UDRHP-I, 13 Notice, 7 Addendum cum Corrigendum, 4 Other, 1 RHP. 'All DRHP Filings' has one row per entry.
